Workbook

Sheet Read Me
B2: HOTEL FEASIBILITY CHECK | NBC 2016 (Part 3 & Part 4) based | 60-Key Prototype Model
B4: Purpose | C4: Given a Site Area and permissible FAR, this workbook checks setbacks, achievable height, ground coverage and buildable area (BUA), then plans a hotel keys-count using a 3.5m x 7m room module, 2 cores (1 main + 1 service), 2 passenger lifts + 1 service lift (rear-located), and validates the design against a BUA/Key target of 380-400 sft.
B6: How to use
C7: 1. Go to the 'Inputs' sheet (yellow cells only) — enter Site Area, plot dimensions/shape, road width, FAR, target keys, etc.
C8: 2. 'Setback Calc' auto-derives front/rear/side setbacks from the NBC 2016 Part-3 baseline table + height-linked increment rule, and computes the buildable footprint for your plot shape.
C9: 3. 'Height & FAR Check' compares your proposed height against the NBC road-width height rule and your FAR-permitted BUA.
C10: 4. 'Hotel Program' plans keys/floor from the floor plate, room module, and core areas, and builds up Guestroom + FOH + BOH BUA.
C11: 5. 'Feasibility Summary' gives a one-page GO / REVIEW / NO-GO dashboard.
B13: Important caveat
C14: NBC 2016 is a MODEL / advisory code (Part 3 = Development Control Rules). It becomes legally binding only when adopted into your State/local Building Bye-Laws or Development Control Regulations (e.g. UDCPR-Maharashtra, TNCDBR-Tamil Nadu, Karnataka BBMP/KMC, Delhi UBBL, etc.), which frequently set stricter or different setback, FAR, parking, and height-vs-road-width values than the NBC baseline. All setback/FAR/coverage figures in this sheet are indicative baselines (blue, editable, sourced) — replace them with your local sanctioning authority's DCR values before using this for actual submission or investment decisions. Fire-access, structural, MEP and lift-code (Part 4, Part 8) requirements are simplified as area allowances here and must be verified against detailed NBC Part 4 / Part 8 / relevant IS codes and a licensed architect's design.
B16: Colour key
C17: Blue text / yellow fill = editable input
C18: Black text = formula (do not overwrite)
C19: Green text = link pulled from another sheet
C20: Green fill = check passes / Red fill = check fails / Amber = borderline, review
B22: Sheets
C23: • Inputs
C24: • Setback Calc
C25: • Height & FAR Check
C26: • Hotel Program
C27: • Feasibility Summary

Sheet Inputs
B2: INPUTS (edit yellow cells only)
B4: 1. Site Details
B5: Site Area (sqft) | C5: 30000 | E5: Total plot/site area as per title deed / survey.
B6: Site Area (sqm) — auto | C6: =Inputs!$C$5/10.7639 -> 2787.0939
B7: Plot Shape | C7: Rectangular | E7: Irregular plot: enter a Shape Efficiency Factor below instead of exact geometry.
B8: Plot Length (ft) — along depth | C8: 200
B9: Plot Width / Frontage (ft) — along road | C9: 150 | E9: For Rectangular/Corner plots. Length x Width should ≈ Site Area (sqft).
B10: Shape Efficiency Factor (0-1) | C10: 0.9 | E10: Only used if Plot Shape = Irregular. De-rates the notional rectangle footprint for odd/angular boundaries. Use 1.00 for regular sites.
B11: Road Width — main frontage (m) | C11: 12
B12: Road Width — 2nd frontage, if Corner Plot (m) | C12: 9 | E12: Ignored unless Plot Shape = Corner Plot.
B14: 2. Development Control Parameters
B15: Permissible FAR / FSI | C15: 3.25 | E15: Verify with local Development Authority. NBC gives only indicative ranges (1.0-3.5 residential, higher commercial/TOD).
B16: Max Ground Coverage permitted (%) | C16: 0.55
B17: Target no. of floors (incl. ground) | C17: 7
B18: Floor-to-floor ht. — guestroom floors (m) | C18: 3.2
B19: Ground/Lobby floor height (m) | C19: 5.5
B21: 3. Hotel Program Inputs
B22: Target Keys (Guestrooms) | C22: 60
B23: Room Module — Width (m) | C23: 3.5
B24: Room Module — Depth (m) | C24: 7
B25: No. of Cores (minimum) | C25: 2 | E25: 1 Main core (2 passenger lifts + stair + lobby) + 1 Service core (1 service lift + stair), located at rear.
B26: Main Core area — 2 pass. lifts + stair + lobby (sft) | C26: 550
B27: Service Core area — 1 service lift + stair (sft), rear | C27: 320
B28: Net-to-Gross Efficiency — guestroom floor (%) | C28: 0.68 | E28: Room carpet ÷ Efficiency = Gross BUA/key. Tune this to land in the 380-400 sft/key band.
B29: FOH area per 60 keys (sft) | C29: 2800
B30: BOH area per 60 keys (sft) | C30: 2200
B31: BOH Location | C31: Basement
B32: Count BOH in FAR BUA? (Y/N) | C32: N | E32: Most State DCRs exclude basements used for services/parking from FAR — verify locally. Set 'Y' if your local DCR counts it.
B33: Target BUA/Key — low (sft) | C33: 380
B34: Target BUA/Key — high (sft) | C34: 400

Sheet Setback Calc
B2: SETBACK CALCULATION (NBC 2016 Part-3 baseline + height/road-width rules)
B4: 1. NBC 2016 Part-3 Baseline Setback Table (indicative — edit per local DCR)
C5: Plot Area Band (sqm) | D5: Front (m) | E5: Rear (m) | F5: Side (m)
B6: Up to 100 | C6: 1.5 | D6: 1 | E6: 1 | F6: Source: NBC 2016 Part 3 baseline bands commonly reproduced in State Model Building Bye-Laws (2016). ALWAYS replace with your local Development Authority's DCR table — state values often differ (e.g. Bangalore keys front setback to road width in steps of 3/6/9/12/18/24 m; Mumbai UDCPR has its own side-setback formula).
B7: 100 - 150 | C7: 3 | D7: 2 | E7: 1.5
B8: 150 - 300 | C8: 4.5 | D8: 3 | E8: 2
B9: 300 - 500 | C9: 6 | D9: 3 | E9: 3
B10: 500 - 1000 | C10: 6 | D10: 4.5 | E10: 4.5
B11: 1000 - 2000 | C11: 7.5 | D11: 6 | E11: 6
B12: 2000 - 4000 | C12: 9 | D12: 7.5 | E12: 7.5
B13: Above 4000 | C13: 12 | D13: 9 | E13: 9
B15: 2. Baseline Setback Lookup (by your Site Area)
B16: Applicable band | C16: =INDEX(B6:B13,MATCH(Inputs!$C$6,{0,100,150,300,500,1000,2000,4000},1)) -> 2000 - 4000
B17: Baseline Front setback (m) | C17: =INDEX(C6:C13,MATCH(Inputs!$C$6,{0,100,150,300,500,1000,2000,4000},1)) -> 9
B18: Baseline Rear setback (m) | C18: =INDEX(D6:D13,MATCH(Inputs!$C$6,{0,100,150,300,500,1000,2000,4000},1)) -> 7.5
B19: Baseline Side setback (m) | C19: =INDEX(E6:E13,MATCH(Inputs!$C$6,{0,100,150,300,500,1000,2000,4000},1)) -> 7.5
B21: 3. Height-linked Increment (NBC 2016 Pt.3: +0.5m to side & rear per storey above 4)
B22: Storeys above 4 (from Target Floors) | C22: =MAX(0,Inputs!$C$17-4) -> 3
B23: Increment to Rear & Side setback (m) | C23: ='Setback Calc'!$C$22*0.5 -> 1.5 | E23: Applies above 4 storeys; most State DCRs adopt some version of this progression — confirm local multiplier.
B25: 4. Adopted Setbacks (Baseline + Increment, editable override in col D)
C26: Computed (m) | D26: Adopted Override — leave blank to use Computed | E26: Adopted (ft, used downstream)
B27: Front setback | C27: ='Setback Calc'!$C$17 -> 9 | E27: =IF(D27="",C27,D27)*3.28084 -> 29.52756
B28: Rear setback | C28: ='Setback Calc'!$C$18+'Setback Calc'!$C$23 -> 9 | E28: =IF(D28="",C28,D28)*3.28084 -> 29.52756
B29: Side setback (each side) | C29: ='Setback Calc'!$C$19+'Setback Calc'!$C$23 -> 9 | E29: =IF(D29="",C29,D29)*3.28084 -> 29.52756
B30: Rule check: minimum side setback of 1.2 m required wherever side rooms have habitable openings (NBC Part 4, fire-access). Adopted side setback above already exceeds this at all but the smallest plot bands — verify for your plot band.
B32: 5. Buildable Footprint (depends on Plot Shape)
B33: Frontages requiring Front setback | C33: =IF(Inputs!$C$7="Corner Plot (2 roads)",2,1) -> 1
B34: Notional rectangle footprint (sft) | C34: =MAX(0,(Inputs!$C$8-'Setback Calc'!$E$27-'Setback Calc'!$E$28)*(Inputs!$C$9-2*'Setback Calc'!$E$29-('Setback Calc'!$C$33-1)*'Setback Calc'!$E$27)) -> 12818.215 | E34: Depth reduced by front+rear; width reduced by 2 side setbacks. Corner plot: 2nd frontage also loses a front setback instead of a side setback.
B35: Shape factor applied | C35: =IF(Inputs!$C$7="Irregular",Inputs!$C$10,1) -> 1
B36: Buildable Footprint / Max Floor Plate (sft) | C36: ='Setback Calc'!$C$34*'Setback Calc'!$C$35 -> 12818.215
B37: Ground Coverage achieved (%) | C37: ='Setback Calc'!$C$36/Inputs!$C$5 -> 0.42727384
B38: Max Ground Coverage permitted (%) | C38: =Inputs!$C$16 -> 0.55
B39: Ground Coverage Check | C39: =IF('Setback Calc'!$C$37<=Inputs!$C$16,"OK - within limit","EXCEEDS limit, reduce floor plate") -> OK - within limit

Sheet Height & FAR Check
B2: HEIGHT & FAR CHECK
B4: 1. Height Rule Check (NBC 2016 Pt.3: Height ≤ (Road Width + Front Setback) x 1.5)
B5: Road width used (main frontage, m) | C5: =Inputs!$C$11 -> 12
B6: Front setback adopted (m) | C6: ='Setback Calc'!$E$27/3.28084 -> 9
B7: Max Permissible Building Height (m) | C7: =(Inputs!$C$11+'Setback Calc'!$E$27/3.28084)*1.5 -> 31.5 | D7: Applies to residential per NBC baseline; many DCRs extend a similar linkage to other occupancies, and additionally cap absolute height (e.g. High Rise threshold ~15m+ triggers NBC Part 4 fire norms — sprinklers, refuge floors, fire lift). Verify High-Rise classification with local Fire NOC authority.
B8: Proposed Height — guestroom floors (m) | C8: =(Inputs!$C$17-1)*Inputs!$C$18+Inputs!$C$19 -> 24.7 | D8: Formula: (Target floors - 1 ground) x guestroom floor-to-floor + Ground/Lobby floor height.
B9: Height Check | C9: =IF('Height & FAR Check'!$C$8<='Height & FAR Check'!$C$7,"OK - within height rule","EXCEEDS - reduce floors or increase front setback") -> OK - within height rule
B10: Achievable Floors under Height Rule | C10: =1+ROUNDDOWN(('Height & FAR Check'!$C$7-Inputs!$C$19)/Inputs!$C$18,0) -> 9
B12: 2. FAR / BUA Check
B13: Site Area (sft) | C13: =Inputs!$C$5 -> 30000
B14: Permissible FAR | C14: =Inputs!$C$15 -> 3.25
B15: Max Permissible BUA — FAR area (sft) | C15: =Inputs!$C$5*Inputs!$C$15 -> 97500
B16: Buildable Footprint / Floor Plate (sft) | C16: ='Setback Calc'!$C$36 -> 12818.215
B17: Achievable Floors under FAR (Max FAR BUA ÷ Floor Plate) | C17: =IFERROR(ROUNDDOWN('Height & FAR Check'!$C$15/'Setback Calc'!$C$36,0),0) -> 7 | D17: Indicative only — assumes every floor uses the full floor plate at 100% (a real scheme will taper/step back at upper floors, add refuge floor, terrace M&E, etc.)
B18: Governing Achievable Floors (lower of Height-rule & FAR) | C18: =MIN('Height & FAR Check'!$C$10,'Height & FAR Check'!$C$17) -> 7
B19: Target Floors (from Inputs) | C19: =Inputs!$C$17 -> 7
B20: Floors Check | C20: =IF(Inputs!$C$17<='Height & FAR Check'!$C$18,"OK - target achievable","REVIEW - target exceeds achievable floors") -> OK - target achievable

Sheet Hotel Program
B2: HOTEL PROGRAM | Room Module, Cores/Lifts, Keys, FOH/BOH, BUA
B4: 1. Room Module & Gross Area per Key
B5: Room Module (m) | C5: =Inputs!$C$23&" x "&Inputs!$C$24&" m" -> 3.5 x 7 m
B6: Room Net (carpet) Area (sqm) | C6: =Inputs!$C$23*Inputs!$C$24 -> 24.5
B7: Room Net (carpet) Area (sft) | C7: ='Hotel Program'!$C$6*10.7639 -> 263.71555
B8: Net-to-Gross Efficiency (corridor+core+wall load) | C8: =Inputs!$C$28 -> 0.68
B9: Gross BUA per Key (sft) | C9: ='Hotel Program'!$C$7/Inputs!$C$28 -> 387.81699 | D9: This is the all-in BUA/key incl. share of corridor, shafts, walls & cores - compare against the 380-400 sft/key target below.
B11: 2. Cores, Lifts & Keys per Floor
B12: Main Core — 2 Passenger Lifts + Stair + Lift Lobby (sft) | C12: =Inputs!$C$26 -> 550
B13: Service Core — 1 Service Lift + Stair, rear-located (sft) | C13: =Inputs!$C$27 -> 320
B14: Total Core Area per Floor (sft) | C14: =Inputs!$C$26+Inputs!$C$27 -> 870
B15: Buildable Floor Plate (sft) — from Setback Calc | C15: ='Setback Calc'!$C$36 -> 12818.215
B16: Net area available for keys per floor (sft) | C16: =MAX(0,('Setback Calc'!$C$36-'Hotel Program'!$C$14))*Inputs!$C$28 -> 8124.7863 | D16: Formula: (Floor plate - core areas) x efficiency, to also net off corridor/shaft/wall loss beyond the cores.
B17: Keys achievable per Floor | C17: =IFERROR(ROUNDDOWN('Hotel Program'!$C$16/'Hotel Program'!$C$7,0),0) -> 30
B19: 3. Guestroom Floors & Total Keys
B20: Governing Achievable Floors (from Height & FAR Check) | C20: ='Height & FAR Check'!$C$18 -> 7
B21: Guestroom Floors (Governing floors - 1 ground/podium) | C21: =MAX(0,'Hotel Program'!$C$20-1) -> 6
B22: Total Achievable Keys (Keys/floor x Guestroom floors) | C22: ='Hotel Program'!$C$17*'Hotel Program'!$C$21 -> 180
B23: Target Keys (from Inputs) | C23: =Inputs!$C$22 -> 60
B24: Guestroom Floors needed for Target Keys | C24: =IFERROR(ROUNDUP(Inputs!$C$22/'Hotel Program'!$C$17,0),0) -> 2
B25: Keys Check | C25: =IF('Hotel Program'!$C$22>=Inputs!$C$22,"OK - target keys achievable","REVIEW - increase floors/plot or trim target keys") -> OK - target keys achievable
B27: 4. FOH / BOH Area Build-up (scaled from 60-key benchmark)
B28: FOH per 60 keys (sft) | C28: =Inputs!$C$29 -> 2800
B29: BOH per 60 keys (sft) | C29: =Inputs!$C$30 -> 2200
B30: Keys used for scaling (Target Keys) | C30: =Inputs!$C$22 -> 60
B31: FOH Area required (sft) | C31: =Inputs!$C$22/60*Inputs!$C$29 -> 2800
B32: BOH Area required (sft) | C32: =Inputs!$C$22/60*Inputs!$C$30 -> 2200
B33: BOH Location | C33: =Inputs!$C$31 -> Basement
B34: BOH counted in FAR BUA? | C34: =Inputs!$C$32 -> N
B36: 5. Total Built-Up Area Summary
B37: Guestroom Tower BUA (Target Keys x Gross BUA/Key) (sft) | C37: =Inputs!$C$22*'Hotel Program'!$C$9 -> 23269.019
B38: + FOH Area (sft) | C38: ='Hotel Program'!$C$31 -> 2800
B39: + BOH Area (sft) — included per 'Count BOH in FAR' toggle | C39: =IF(Inputs!$C$32="Y",'Hotel Program'!$C$32,0) -> 0
B40: Total BUA counted for FAR compliance (sft) | C40: ='Hotel Program'!$C$37+'Hotel Program'!$C$31+'Hotel Program'!$C$39 -> 26069.019
B41: Max Permissible BUA under FAR (sft) — from Height & FAR Check | C41: ='Height & FAR Check'!$C$15 -> 97500
B42: FAR Compliance Check | C42: =IF('Hotel Program'!$C$40<='Height & FAR Check'!$C$15,"OK - within FAR","EXCEEDS FAR - trim program or increase site/FAR") -> OK - within FAR
B43: Total Development BUA (Guestroom+FOH+BOH, regardless of FAR exemption) (sft) | C43: ='Hotel Program'!$C$37+'Hotel Program'!$C$31+'Hotel Program'!$C$32 -> 28269.019
B45: 6. BUA per Key Feasibility Check (target 380-400 sft)
B46: Overall BUA per Key (Total Dev. BUA ÷ Target Keys) (sft) | C46: ='Hotel Program'!$C$43/Inputs!$C$22 -> 471.15032
B47: Guestroom-only Gross BUA per Key (sft) | C47: ='Hotel Program'!$C$9 -> 387.81699
...

Sheet Feasibility Summary
B2: FEASIBILITY CHECK — SUMMARY DASHBOARD
B3: Reference: NBC 2016 Part 3 (Development Control) baseline, adjusted per local DCR — see 'Read Me' tab for caveats.
B5: Site & Development Parameters
B6: Site Area (sft / sqm) | C6: =Inputs!$C$5&" sft / "&ROUND(Inputs!$C$6,0)&" sqm" -> 30000 sft / 2787 sqm
B7: Plot Shape | C7: =Inputs!$C$7 -> Rectangular
B8: FAR / FSI adopted | C8: =Inputs!$C$15 -> 3.25
B9: Max Permissible BUA (FAR x Site Area) | C9: ='Height & FAR Check'!$C$15 -> 97500
B11: Setback & Ground Coverage Checks
B12: Adopted Front / Rear / Side setback (m) | C12: =ROUND('Setback Calc'!$E$27/3.28084,2)&" / "&ROUND('Setback Calc'!$E$28/3.28084,2)&" / "&ROUND('Setback Calc'!$E$29/3.28084,2) -> 9 / 9 / 9
B13: Buildable Floor Plate (sft) | C13: ='Setback Calc'!$C$36 -> 12818.215
B14: Ground Coverage Check | C14: ='Setback Calc'!$C$39 -> OK - within limit
B16: Height & Floors Checks
B17: Max Permissible Height, NBC rule (m) | C17: ='Height & FAR Check'!$C$7 -> 31.5
B18: Proposed Height (m) | C18: ='Height & FAR Check'!$C$8 -> 24.7
B19: Height Check | C19: ='Height & FAR Check'!$C$9 -> OK - within height rule
B20: Governing Achievable Floors | C20: ='Height & FAR Check'!$C$18 -> 7
B21: Target Floors | C21: =Inputs!$C$17 -> 7
B22: Floors Check | C22: ='Height & FAR Check'!$C$20 -> OK - target achievable
B24: Hotel Program — Keys & Areas
B25: Keys achievable per Floor | C25: ='Hotel Program'!$C$17 -> 30
B26: Guestroom Floors | C26: ='Hotel Program'!$C$21 -> 6
B27: Total Achievable Keys | C27: ='Hotel Program'!$C$22 -> 180
B28: Target Keys | C28: =Inputs!$C$22 -> 60
B29: Keys Check | C29: ='Hotel Program'!$C$25 -> OK - target keys achievable
B30: FOH Area required (sft) | C30: ='Hotel Program'!$C$31 -> 2800
B31: BOH Area required (sft) | C31: ='Hotel Program'!$C$32 -> 2200
B32: Guestroom Tower BUA (sft) | C32: ='Hotel Program'!$C$37 -> 23269.019
B33: Total BUA counted for FAR (sft) | C33: ='Hotel Program'!$C$40 -> 26069.019
B34: FAR Compliance Check | C34: ='Hotel Program'!$C$42 -> OK - within FAR
B36: BUA per Key Check (target 380-400 sft)
B37: Guestroom-only Gross BUA per Key (sft) | C37: ='Hotel Program'!$C$9 -> 387.81699
B38: Overall BUA per Key incl. FOH+BOH (sft) | C38: ='Hotel Program'!$C$46 -> 471.15032
B39: BUA/Key Check | C39: ='Hotel Program'!$C$50 -> OK - within target band
B41: OVERALL FEASIBILITY VERDICT
B42: Verdict | C42: =IF(COUNTIF(C14,"EX*")+COUNTIF(C19,"EX*")+COUNTIF(C22,"RE*")+COUNTIF(C29,"RE*")+COUNTIF(C34,"EX*")+COUNTIF(C39,"BE*")+COUNTIF(C39,"ABO*")=0,"GO - scheme meets NBC-baseline checks (verify local DCR)","REVIEW REQUIRED - one or more checks fail, see flags above") -> GO - scheme meets NBC-baseline checks (verify local DCR)
B44: This dashboard is a planning-stage screening tool, not a substitute for a sanctioned architectural drawing, structural/fire NOC, or statutory approval. Verify all figures against the local Development Authority's current Building Bye-Laws / DCR before proceeding to design development or investment commitment.
